Workbook
Name AllData: Report!$A$11:$G$563

Sheet Data
A1: CompanyName | B1: Escuela de Ingenieria Electrica UCR
A2: RunDate | B2: 46091.357
A3: FromDate | B3: 46087
A4: ToDate | B4: 46087.433
A5: TimeZone | B5: America/Costa_Rica
A6: SendReport | B6: TRUE
A7: LastModifiedUser | B7: System
A8: Language | B8: es
A9: .StatusData.Device.DeviceName | B9: .StatusData.Device.DeviceId | C9: .StatusData.Device.DeviceComment | D9: .StatusData.Device.DeviceGroup | E9: .Device.DeviceGroup|Company Group | F9: StatusDataDateTime | G9: .StatusData.Diagnostic.DiagnosticName | H9: .StatusData.Diagnostic.DiagnosticId | I9: .StatusData.Diagnostic.DiagnosticCode | J9: .StatusData.Diagnostic.Source.SourceName | K9: .StatusData.Diagnostic.Source.SourceId | L9: .StatusData.Diagnostic.Controller.ControllerName | M9: .StatusData.Diagnostic.Controller.ControllerId | N9: StatusDataRecordDisplayData | O9: SensorDataAddress | P9: StatusDataRecordUnitOfMeasureName | Q9: .StatusData.Diagnostic.UnitOfMeasure.UnitOfMeasureId
A10: NISSAN LEAF 299-1018 | B10: b3 | D10: Vehicle, Battery Electric Vehicle | E10: Battery Electric Vehicle, Vehicle | F10: 46087.291 | G10: Estado de carga genérico | H10: DiagnosticStateOfChargeId | I10: 2118 | J10: Telematics Device | K10: SourceGeotabGoId | M10: ControllerNoneId | N10: 78.66 | P10: % | Q10: UnitOfMeasurePercentageId
A11: NISSAN LEAF 299-1018 | B11: b3 | D11: Vehicle, Battery Electric Vehicle | E11: Battery Electric Vehicle, Vehicle | F11: 46087.291 | G11: Voltaje de la batería de alta tensión | H11: a4kUpYGyQ4E2uoQTp-ed0Ow | I11: 2111 | J11: Telematics Device | K11: SourceGeotabGoId | M11: ControllerNoneId | N11: 376 | P11: V | Q11: UnitOfMeasureVoltsId
A12: NISSAN LEAF 299-1018 | B12: b3 | D12: Vehicle, Battery Electric Vehicle | E12: Battery Electric Vehicle, Vehicle | F12: 46087.291 | G12: Energía de la batería del vehículo eléctrico | H12: DiagnosticElectricVehicleBatteryPowerId | I12: 3294 | J12: Telematics Device | K12: SourceGeotabGoId | M12: ControllerNoneId | N12: 564 | P12: W | Q12: UnitOfMeasureWattsId
A13: NISSAN LEAF 299-1018 | B13: b3 | D13: Vehicle, Battery Electric Vehicle | E13: Battery Electric Vehicle, Vehicle | F13: 46087.293 | G13: Estado de carga genérico | H13: DiagnosticStateOfChargeId | I13: 2118 | J13: Telematics Device | K13: SourceGeotabGoId | M13: ControllerNoneId | N13: 78.66 | P13: % | Q13: UnitOfMeasurePercentageId
A14: NISSAN LEAF 299-1018 | B14: b3 | D14: Vehicle, Battery Electric Vehicle | E14: Battery Electric Vehicle, Vehicle | F14: 46087.293 | G14: Voltaje de la batería de alta tensión | H14: a4kUpYGyQ4E2uoQTp-ed0Ow | I14: 2111 | J14: Telematics Device | K14: SourceGeotabGoId | M14: ControllerNoneId | N14: 376 | P14: V | Q14: UnitOfMeasureVoltsId
A15: NISSAN LEAF 299-1018 | B15: b3 | D15: Vehicle, Battery Electric Vehicle | E15: Battery Electric Vehicle, Vehicle | F15: 46087.293 | G15: Energía de la batería del vehículo eléctrico | H15: DiagnosticElectricVehicleBatteryPowerId | I15: 3294 | J15: Telematics Device | K15: SourceGeotabGoId | M15: ControllerNoneId | N15: 188 | P15: W | Q15: UnitOfMeasureWattsId
A16: NISSAN LEAF 299-1018 | B16: b3 | D16: Vehicle, Battery Electric Vehicle | E16: Battery Electric Vehicle, Vehicle | F16: 46087.298 | G16: Estado de carga genérico | H16: DiagnosticStateOfChargeId | I16: 2118 | J16: Telematics Device | K16: SourceGeotabGoId | M16: ControllerNoneId | N16: 78.66 | P16: % | Q16: UnitOfMeasurePercentageId
A17: NISSAN LEAF 299-1018 | B17: b3 | D17: Vehicle, Battery Electric Vehicle | E17: Battery Electric Vehicle, Vehicle | F17: 46087.298 | G17: Voltaje de la batería de alta tensión | H17: a4kUpYGyQ4E2uoQTp-ed0Ow | I17: 2111 | J17: Telematics Device | K17: SourceGeotabGoId | M17: ControllerNoneId | N17: 376 | P17: V | Q17: UnitOfMeasureVoltsId
A18: NISSAN LEAF 299-1018 | B18: b3 | D18: Vehicle, Battery Electric Vehicle | E18: Battery Electric Vehicle, Vehicle | F18: 46087.298 | G18: Energía de la batería del vehículo eléctrico | H18: DiagnosticElectricVehicleBatteryPowerId | I18: 3294 | J18: Telematics Device | K18: SourceGeotabGoId | M18: ControllerNoneId | N18: 376 | P18: W | Q18: UnitOfMeasureWattsId
A19: NISSAN LEAF 299-1018 | B19: b3 | D19: Vehicle, Battery Electric Vehicle | E19: Battery Electric Vehicle, Vehicle | F19: 46087.299 | G19: Energía de la batería del vehículo eléctrico | H19: DiagnosticElectricVehicleBatteryPowerId | I19: 3294 | J19: Telematics Device | K19: SourceGeotabGoId | M19: ControllerNoneId | N19: 22134 | P19: W | Q19: UnitOfMeasureWattsId
A20: NISSAN LEAF 299-1018 | B20: b3 | D20: Vehicle, Battery Electric Vehicle | E20: Battery Electric Vehicle, Vehicle | F20: 46087.299 | G20: Energía de la batería del vehículo eléctrico | H20: DiagnosticElectricVehicleBatteryPowerId | I20: 3294 | J20: Telematics Device | K20: SourceGeotabGoId | M20: ControllerNoneId | N20: -26320 | P20: W | Q20: UnitOfMeasureWattsId
A21: NISSAN LEAF 299-1018 | B21: b3 | D21: Vehicle, Battery Electric Vehicle | E21: Battery Electric Vehicle, Vehicle | F21: 46087.299 | G21: Energía de la batería del vehículo eléctrico | H21: DiagnosticElectricVehicleBatteryPowerId | I21: 3294 | J21: Telematics Device | K21: SourceGeotabGoId | M21: ControllerNoneId | N21: 19183 | P21: W | Q21: UnitOfMeasureWattsId
... A561: NISSAN LEAF 299-1018 | B561: b3 | D561: Vehicle, Battery Electric Vehicle | E561: Battery Electric Vehicle, Vehicle | F561: 46087.432 | G561: Energía de la batería del vehículo eléctrico | H561: DiagnosticElectricVehicleBatteryPowerId | I561: 3294 | J561: Telematics Device | K561: SourceGeotabGoId | M561: ControllerNoneId | N561: -15246 | P561: W | Q561: UnitOfMeasureWattsId

Sheet Report
A1: Reporte de estado del motor | C1: =Data!B2 -> 46091.357
A2: =Data!B1 -> Escuela de Ingenieria Electrica UCR
A4: Fecha
A5: Desde | B5: =Data!B3 -> 46087
A6: Hasta | B6: =Data!B4 -> 46087.433
A7: Días | B7: =B6-B5 -> 0.43332176
A9: Huso horario | B9: =Data!B5 -> America/Costa_Rica
A11: Dispositivo | B11: Grupo de dispositivos | C11: Fecha | D11: Descripción | E11: Fuente | F11: Controlador de motor | G11: Valor
A12: =Data!A10 -> NISSAN LEAF 299-1018 | B12: =Data!D10 -> Vehicle, Battery Electric Vehicle | C12: =Data!F10 -> 46087.291 | D12: =Data!G10 -> Estado de carga genérico | E12: =Data!J10 -> Telematics Device | F12: =Data!L10 -> 0 | G12: =CONCATENATE(Data!N10," ",Data!P10) -> 78.66 %
A13: =Data!A11 -> NISSAN LEAF 299-1018 | B13: =Data!D11 -> Vehicle, Battery Electric Vehicle | C13: =Data!F11 -> 46087.291 | D13: =Data!G11 -> Voltaje de la batería de alta tensión | E13: =Data!J11 -> Telematics Device | F13: =Data!L11 -> 0 | G13: =CONCATENATE(Data!N11," ",Data!P11) -> 376 V
A14: =Data!A12 -> NISSAN LEAF 299-1018 | B14: =Data!D12 -> Vehicle, Battery Electric Vehicle | C14: =Data!F12 -> 46087.291 | D14: =Data!G12 -> Energía de la batería del vehículo eléctrico | E14: =Data!J12 -> Telematics Device | F14: =Data!L12 -> 0 | G14: =CONCATENATE(Data!N12," ",Data!P12) -> 564 W
A15: =Data!A13 -> NISSAN LEAF 299-1018 | B15: =Data!D13 -> Vehicle, Battery Electric Vehicle | C15: =Data!F13 -> 46087.293 | D15: =Data!G13 -> Estado de carga genérico | E15: =Data!J13 -> Telematics Device | F15: =Data!L13 -> 0 | G15: =CONCATENATE(Data!N13," ",Data!P13) -> 78.66 %
A16: =Data!A14 -> NISSAN LEAF 299-1018 | B16: =Data!D14 -> Vehicle, Battery Electric Vehicle | C16: =Data!F14 -> 46087.293 | D16: =Data!G14 -> Voltaje de la batería de alta tensión | E16: =Data!J14 -> Telematics Device | F16: =Data!L14 -> 0 | G16: =CONCATENATE(Data!N14," ",Data!P14) -> 376 V
A17: =Data!A15 -> NISSAN LEAF 299-1018 | B17: =Data!D15 -> Vehicle, Battery Electric Vehicle | C17: =Data!F15 -> 46087.293 | D17: =Data!G15 -> Energía de la batería del vehículo eléctrico | E17: =Data!J15 -> Telematics Device | F17: =Data!L15 -> 0 | G17: =CONCATENATE(Data!N15," ",Data!P15) -> 188 W
A18: =Data!A16 -> NISSAN LEAF 299-1018 | B18: =Data!D16 -> Vehicle, Battery Electric Vehicle | C18: =Data!F16 -> 46087.298 | D18: =Data!G16 -> Estado de carga genérico | E18: =Data!J16 -> Telematics Device | F18: =Data!L16 -> 0 | G18: =CONCATENATE(Data!N16," ",Data!P16) -> 78.66 %
A19: =Data!A17 -> NISSAN LEAF 299-1018 | B19: =Data!D17 -> Vehicle, Battery Electric Vehicle | C19: =Data!F17 -> 46087.298 | D19: =Data!G17 -> Voltaje de la batería de alta tensión | E19: =Data!J17 -> Telematics Device | F19: =Data!L17 -> 0 | G19: =CONCATENATE(Data!N17," ",Data!P17) -> 376 V
A20: =Data!A18 -> NISSAN LEAF 299-1018 | B20: =Data!D18 -> Vehicle, Battery Electric Vehicle | C20: =Data!F18 -> 46087.298 | D20: =Data!G18 -> Energía de la batería del vehículo eléctrico | E20: =Data!J18 -> Telematics Device | F20: =Data!L18 -> 0 | G20: =CONCATENATE(Data!N18," ",Data!P18) -> 376 W
A21: =Data!A19 -> NISSAN LEAF 299-1018 | B21: =Data!D19 -> Vehicle, Battery Electric Vehicle | C21: =Data!F19 -> 46087.299 | D21: =Data!G19 -> Energía de la batería del vehículo eléctrico | E21: =Data!J19 -> Telematics Device | F21: =Data!L19 -> 0 | G21: =CONCATENATE(Data!N19," ",Data!P19) -> 22134 W
A22: =Data!A20 -> NISSAN LEAF 299-1018 | B22: =Data!D20 -> Vehicle, Battery Electric Vehicle | C22: =Data!F20 -> 46087.299 | D22: =Data!G20 -> Energía de la batería del vehículo eléctrico | E22: =Data!J20 -> Telematics Device | F22: =Data!L20 -> 0 | G22: =CONCATENATE(Data!N20," ",Data!P20) -> -26320 W
A23: =Data!A21 -> NISSAN LEAF 299-1018 | B23: =Data!D21 -> Vehicle, Battery Electric Vehicle | C23: =Data!F21 -> 46087.299 | D23: =Data!G21 -> Energía de la batería del vehículo eléctrico | E23: =Data!J21 -> Telematics Device | F23: =Data!L21 -> 0 | G23: =CONCATENATE(Data!N21," ",Data!P21) -> 19183 W
... A563: =Data!A561 -> NISSAN LEAF 299-1018 | B563: =Data!D561 -> Vehicle, Battery Electric Vehicle | C563: =Data!F561 -> 46087.432 | D563: =Data!G561 -> Energía de la batería del vehículo eléctrico | E563: =Data!J561 -> Telematics Device | F563: =Data!L561 -> 0 | G563: =CONCATENATE(Data!N561," ",Data!P561) -> -15246 W

Sheet Summary
A1: Reporte de estado del motor | C1: =Data!B2 -> 46091.357
A2: =Data!B1 -> Escuela de Ingenieria Electrica UCR
A4: Fecha
A5: Desde | B5: =Data!B3 -> 46087
A6: Hasta | B6: =Data!B4 -> 46087.433
A7: Días | B7: =B6-B5 -> 0.43332176
A9: Huso horario | B9: =Data!B5 -> America/Costa_Rica
A12: Dispositivo | B12: Grupo de dispositivos | C12: Fecha | D12: Descripción | E12: Fuente | F12: Controlador de motor | G12: Valor
A13: NISSAN LEAF 299-1018 | B13: Vehicle, Battery Electric Vehicle | C13: 46087.291 | D13: Estado de carga genérico | E13: Telematics Device | F13: 0 | G13: 78.66 %
D14: Voltaje de la batería de alta tensión | E14: Telematics Device | F14: 0 | G14: 376 V
D15: Energía de la batería del vehículo eléctrico | E15: Telematics Device | F15: 0 | G15: 564 W
C16: 46087.293 | D16: Estado de carga genérico | E16: Telematics Device | F16: 0 | G16: 78.66 %
C17: 46087.293 | D17: Voltaje de la batería de alta tensión | E17: Telematics Device | F17: 0 | G17: 376 V
D18: Energía de la batería del vehículo eléctrico | E18: Telematics Device | F18: 0 | G18: 188 W
C19: 46087.298 | D19: Estado de carga genérico | E19: Telematics Device | F19: 0 | G19: 78.66 %
D20: Voltaje de la batería de alta tensión | E20: Telematics Device | F20: 0 | G20: 376 V
D21: Energía de la batería del vehículo eléctrico | E21: Telematics Device | F21: 0 | G21: 376 W
C22: 46087.299 | D22: Energía de la batería del vehículo eléctrico | E22: Telematics Device | F22: 0 | G22: 22134 W
C23: 46087.299 | D23: Energía de la batería del vehículo eléctrico | E23: Telematics Device | F23: 0 | G23: -26320 W
C24: 46087.299 | D24: Energía de la batería del vehículo eléctrico | E24: Telematics Device | F24: 0 | G24: 19183 W
C25: 46087.299 | D25: Energía de la batería del vehículo eléctrico | E25: Telematics Device | F25: 0 | G25: -23027 W
C26: 46087.299 | D26: Energía de la batería del vehículo eléctrico | E26: Telematics Device | F26: 0 | G26: -29585 W
C27: 46087.299 | D27: Energía de la batería del vehículo eléctrico | E27: Telematics Device | F27: 0 | G27: 0 W
C28: 46087.3 | D28: Energía de la batería del vehículo eléctrico | E28: Telematics Device | F28: 0 | G28: 20673 W
C29: 46087.3 | D29: Energía de la batería del vehículo eléctrico | E29: Telematics Device | F29: 0 | G29: -31563 W
C30: 46087.3 | D30: Energía de la batería del vehículo eléctrico | E30: Telematics Device | F30: 0 | G30: 24000 W
C31: 46087.3 | D31: Energía de la batería del vehículo eléctrico | E31: Telematics Device | F31: 0 | G31: -16875 W
C32: 46087.3 | D32: Energía de la batería del vehículo eléctrico | E32: Telematics Device | F32: 0 | G32: 19396 W
C33: 46087.3 | D33: Energía de la batería del vehículo eléctrico | E33: Telematics Device | F33: 0 | G33: -749 W
... C69: 46087.308 | D69: Voltaje de la batería de alta tensión | E69: Telematics Device | F69: 0 | G69: 372.5 V
D70: Energía de la batería del vehículo eléctrico | E70: Telematics Device | F70: 0 | G70: 186 W
C71: 46087.352 | D71: Estado de carga genérico | E71: Telematics Device | F71: 0 | G71: 76.585 %
D72: Voltaje de la batería de alta tensión | E72: Telematics Device | F72: 0 | G72: 373 V
D73: Energía de la batería del vehículo eléctrico | E73: Telematics Device | F73: 0 | G73: 373 W
C74: 46087.356 | D74: Energía de la batería del vehículo eléctrico | E74: Telematics Device | F74: 0 | G74: -21820 W
C75: 46087.356 | D75: Energía de la batería del vehículo eléctrico | E75: Telematics Device | F75: 0 | G75: 8556 W
C76: 46087.357 | D76: Energía de la batería del vehículo eléctrico | E76: Telematics Device | F76: 0 | G76: 11501 W
C77: 46087.357 | D77: Energía de la batería del vehículo eléctrico | E77: Telematics Device | F77: 0 | G77: 4855 W
C78: 46087.357 | D78: Energía de la batería del vehículo eléctrico | E78: Telematics Device | F78: 0 | G78: -34689 W
C79: 46087.357 | D79: Energía de la batería del vehículo eléctrico | E79: Telematics Device | F79: 0 | G79: 9911 W
...

Sheet Languages
A1: English | B1: French Canada | C1: Spanish | D1: German | E1: Japanese | F1: Polish | G1: Portuguese-Brazil | H1: Dutch | I1: Italian | J1: Simplified Chinese | K1: Thai | L1: Indonesian | M1: Czech | N1: Swedish | O1: Turkish | P1: Malay | Q1: French France | R1: Korean | S1: Traditional Chinese | T1: Danish | U1: Finnish | V1: Hungarian | W1: Norwegian | X1: Slovak | Y1: Portuguese-Portugal | Z1: Romanian
A2: **Device | B2: Dispositif | C2: Dispositivo | D2: Gerät | E2: デバイス | F2: Urzadzenie | G2: Dispositivo | H2: Apparaat | I2: Dispositivo | J2: 设备 | K2: อุปกรณ์ | L2: Perangkat | M2: Zařízení | N2: Enhet | O2: Aygıt | P2: Peranti | Q2: Boîtier | R2: 장치 | S2: 裝置 | T2: Enhed | U2: Laite | V2: Készülék | W2: Enhet | X2: Zariadenie | Y2: Dispositivo | Z2: Dispozitiv
A3: **Device Group | B3: Groupe de dispositifs | C3: Grupo de dispositivos | D3: Gerätegruppe | E3: デバイスグループ | F3: Grupa urzadzen | G3: Grupo de dispositivo | H3: Apparaatgroep | I3: Gruppo di dispositivi | J3: 设备的组名 | K3: กลุ่มอุปกรณ์ | L3: Grup Perangkat | M3: Skupina zařízení | N3: Enhetsgrupp | O3: Aygıt Grubu | P3: Kumpulan Peranti | Q3: Groupe de boîtiers | R3: 장치 그룹 | S3: 裝置群組 | T3: Enhedsgruppe | U3: Laiteryhmä | V3: Készülékcsoport | W3: Enhetsgruppe | X3: Skupina zariadení | Y3: Grupo do dispositivo | Z3: Grup de dispozitive
A4: **Date | B4: Date | C4: Fecha | D4: Datum | E4: データ | F4: Data | G4: Data | H4: Datum | I4: Data | J4: 日期 | K4: วันที่ | L4: Tanggal | M4: Datum | N4: Datum | O4: Tarih | P4: Tarikh | Q4: Date | R4: 날짜 | S4: 日期 | T4: Dato | U4: Päivämäärä | V4: Dátum | W4: Dato | X4: Dátum | Y4: Data | Z4: Data
A5: **Description | B5: Description | C5: Descripción | D5: Beschreibung | E5: 説明を入力してください | F5: Opis | G5: Descrição | H5: Omschrijving | I5: Descrizione | J5: 描述 | K5: คำอธิบาย | L5: Deskripsi | M5: Popis | N5: Beskrivning | O5: Açıklama | P5: Huraian | Q5: Description | R5: 설명 | S5: 描述 | T5: Beskrivelse | U5: Kuvaus | V5: Leírás | W5: Beskrivelse | X5: Opis | Y5: Descrição | Z5: Descriere
A6: **Source | B6: Source | C6: Fuente | D6: Quelle | E6: ソース | F6: Zródlo | G6: Fonte | H6: Bron | I6: Sorgente | J6: 来源 | K6: แหล่ง | L6: Sumber | M6: Zdroj | N6: Källa | O6: Kaynak | P6: Sumber | Q6: Source | R6: 소스 | S6: 來源 | T6: Kilde | U6: Lähde | V6: Forrás | W6: Kilde | X6: Zdroj | Y6: Fonte | Z6: Sursă
A7: **Controller | B7: Contrôleur du moteur | C7: Controlador de motor | D7: Motorsteuerung | E7: コントローラー | F7: Kontroler | G7: Controlador | H7: Controller | I7: Controller | J7: 控制器 | K7: ตัวควบคุม | L7: Pengontrol | M7: Ovladač | N7: Kontrollant | O7: Kontrol Aygıtı | P7: Pengawal | Q7: Contrôleur | R7: 컨트롤러 | S7: 控制器 | T7: Controller | U7: Ohjain | V7: Vezérlő | W7: Kontroller | X7: Riadiaca jednotka | Y7: Controlador | Z7: Controler
A8: **Value | B8: Valeur | C8: Valor | D8: Wert | E8: 値 | F8: Wartosc | G8: Valor | H8: Waarde | I8: Valore | J8: 值 | K8: ค่า | L8: Nilai | M8: Hodnota | N8: Värde | O8: Değer | P8: Nilai | Q8: Valeur | R8: 값 | S8: 值 | T8: Værdi | U8: Arvo | V8: Érték | W8: Verdi | X8: Hodnota | Y8: Valor | Z8: Valoare
A9: **Engine Status Report | B9: Rapport d’état du moteur | C9: Reporte de estado del motor | D9: Bericht Motorstatus | E9: エンジン状態レポート | F9: Raport stanu silnika | G9: Relatório do status do motor | H9: Rapport Motorstatus | I9: Report di stato del motore | J9: 发动机状态报告 | K9: รายงานสถานะเครื่องยนต์ | L9: Laporan Status Mesin | M9: Výkaz o stavu motoru | N9: Motorstatusrapport | O9: Motor Durum Raporu | P9: Laporan Status Enjin | Q9: Rapport de l’état du moteur | R9: 엔진 상태 보고서 | S9: 引擎狀態報告 | T9: Motorstatusrapport | U9: Moottorin tilaraportti | V9: Motorállapot-jelentés | W9: Statusrapport for motor | X9: Výkaz stavu motora | Y9: Relatório Estado do motor | Z9: Raport de stare a motorului
A10: **Created | B10: Créé | C10: Creado | D10: Angelegt | E10: 作成済 | F10: Utworzono | G10: Criado em | H10: Aangemaakt | I10: Creato | J10: 创建日期 | K10: สร้างแล้ว | L10: Dibuat | M10: Vytvořeno | N10: Skapad | O10: Oluşturuldu | P10: Dicipta | Q10: Créé | R10: 생성됨 | S10: 已建立 | T10: Oprettet | U10: Luotu | V10: Létrehozva | W10: Opprettet | X10: Vytvorené | Y10: Criado | Z10: Creat
A11: **From | B11: Du | C11: Desde | D11: Von | E11: 開始日 | F11: Od | G11: Desde | H11: Van | I11: Dal | J11: 自 | K11: จาก | L11: Dari | M11: Od | N11: Från | O11: Gönderen | P11: Daripada | Q11: À partir du | R11: 시작 | S11: 從 | T11: Fra | U11: Alku | V11: Feladó | W11: Fra | X11: Z | Y11: De | Z11: De la
A12: **To | B12: Au | C12: Hasta | D12: Bis | E12: 終了日 | F12: Do | G12: Até | H12: Tot | I12: Al | J12: 至 | K12: ถึง | L12: Hingga | M12: Do/pro | N12: Till | O12: Alıcı | P12: Ke | Q12: À | R12: 대상 | S12: 至 | T12: Til | U12: Kohde | V12: Címzett | W12: Til | X12: Do | Y12: A | Z12: Către
... A14: **Days | B14: Jours | C14: Días | D14: Tage | E14: 日 | F14: Dni | G14: Dias | H14: Dagen | I14: Giorni | J14: 天 | K14: วัน | L14: Hari | M14: Dny | N14: Dagar | O14: Gün | P14: hari | Q14: jours | R14: 일 | S14: 天 | T14: Dage | U14: Päivät | V14: Napok | W14: Dager | X14: Dni | Y14: Dias | Z14: Zile
