Workbook
Name AllData: Report!$A$13:$T$6550

Sheet Data
A1: CompanyName | B1: Escuela de Ingenieria Electrica UCR
A2: RunDate | B2: 46091.35
A3: FromDate | B3: 46087.352
A4: ToDate | B4: 46087.486
A5: TimeZone | B5: America/Costa_Rica
A6: SpeedUnit | B6: km/h
A7: SendReport | B7: =TRUE() -> TRUE
A8: LastModifiedUser | B8: **<No User>
A9: Language | B9: es
A10: DeviceName | B10: DeviceId | C10: DeviceGroup | D10: DeviceGroup|Company Group | E10: DeviceComment | F10: UserFirstName | G10: UserLastName | H10: UserName | I10: DebugDateTime | J10: DebugRecordType | K10: DebugSpeed | L10: DebugLongitude | M10: DebugLatitude | N10: DebugRecordReason | O10: DebugIgnition | P10: DebugAux1 | Q10: DebugAux2 | R10: DebugAux3 | S10: DebugAux4 | T10: DebugAux5 | U10: DebugAux6 | V10: DebugAux7 | W10: DebugAux8 | X10: DebugPositionValid | Y10: DebugPositionValidAtUnit | Z10: DebugLoadedSection | AA10: DebugDataLength | AB10: DiagnosticName | AC10: DiagnosticId | AD10: ControllerName | AE10: ControllerId | AF10: FailureModeName | AG10: FailureModeId | AH10: DebuggingStatusRecordDisplayData | AI10: DebuggingStatusRecordUnitOfMeasureName | AJ10: UnitOfMeasureId | AK10: DebugRecordDataInHex
A11: NISSAN LEAF 299-1018 | B11: b3 | C11: Vehicle, Battery Electric Vehicle | D11: Battery Electric Vehicle, Vehicle | I11: 46087.352 | J11: GpsRecord | K11: 0 | L11: -84.04376 | M11: 9.93678 | N11: Ignition | O11: TRUE | P11: FALSE | Q11: FALSE | R11: FALSE | S11: FALSE | T11: FALSE | U11: FALSE | V11: FALSE | W11: FALSE | X11: TRUE | Y11: TRUE
A12: NISSAN LEAF 299-1018 | B12: b3 | C12: Vehicle, Battery Electric Vehicle | D12: Battery Electric Vehicle, Vehicle | I12: 46087.352 | J12: EngineStatusRecord | AB12: PositionValidAtDevice | AC12: DiagnosticPositionValidAtDeviceId | AE12: ControllerNoneId | AH12: 1 | AI12: None | AJ12: UnitOfMeasureNoneId
A13: NISSAN LEAF 299-1018 | B13: b3 | C13: Vehicle, Battery Electric Vehicle | D13: Battery Electric Vehicle, Vehicle | I13: 46087.352 | J13: EngineStatusRecord | O13: TRUE | AB13: Ignición | AC13: DiagnosticIgnitionId | AE13: ControllerNoneId | AH13: 1 | AI13: None | AJ13: UnitOfMeasureNoneId
A14: NISSAN LEAF 299-1018 | B14: b3 | C14: Vehicle, Battery Electric Vehicle | D14: Battery Electric Vehicle, Vehicle | I14: 46087.352 | J14: DebugRecord | N14: ReportOnIoxsConnected | AK14: FE-FE-FE-FE-FE-FE-FE-00-00-00-00-00-00-00-00
A15: NISSAN LEAF 299-1018 | B15: b3 | C15: Vehicle, Battery Electric Vehicle | D15: Battery Electric Vehicle, Vehicle | I15: 46087.352 | J15: DebugRecord | N15: 61393 | AK15: 49-FC-FC-FF-26-00-00-00-00-00-00-00-00-00-00
A16: NISSAN LEAF 299-1018 | B16: b3 | C16: Vehicle, Battery Electric Vehicle | D16: Battery Electric Vehicle, Vehicle | I16: 46087.352 | J16: DebugRecord | N16: 61161 | AK16: 56-01-55-01-50-01-00-00-00-00-00-00-00-00-00
A17: NISSAN LEAF 299-1018 | B17: b3 | C17: Vehicle, Battery Electric Vehicle | D17: Battery Electric Vehicle, Vehicle | I17: 46087.352 | J17: EngineStatusRecord | AB17: Carburador de paso | AC17: aVVhkvxM34U6-4caL3hDQmg | AE17: ControllerNoneId | AH17: 6 | AI17: None | AJ17: UnitOfMeasureNoneId
A18: NISSAN LEAF 299-1018 | B18: b3 | C18: Vehicle, Battery Electric Vehicle | D18: Battery Electric Vehicle, Vehicle | I18: 46087.352 | J18: GpsRecord | K18: 0 | L18: -84.04376 | M18: 9.93678 | N18: CurveOtherEvent | O18: TRUE | P18: FALSE | Q18: FALSE | R18: FALSE | S18: FALSE | T18: FALSE | U18: FALSE | V18: FALSE | W18: FALSE | X18: TRUE | Y18: TRUE
A19: NISSAN LEAF 299-1018 | B19: b3 | C19: Vehicle, Battery Electric Vehicle | D19: Battery Electric Vehicle, Vehicle | I19: 46087.352 | J19: DebugRecord | N19: 60927 | AK19: 0B-01-00-01-01-00-00-00-00-00-00-00-00-00-00
A20: NISSAN LEAF 299-1018 | B20: b3 | C20: Vehicle, Battery Electric Vehicle | D20: Battery Electric Vehicle, Vehicle | I20: 46087.352 | J20: EngineStatusRecord | AB20: Contrato de datos genéricos del vehículo activo | AC20: anjw6IIGoRU2ZHeUKGlekpg | AE20: ControllerNoneId | AH20: 1 | AI20: None | AJ20: UnitOfMeasureNoneId
A21: NISSAN LEAF 299-1018 | B21: b3 | C21: Vehicle, Battery Electric Vehicle | D21: Battery Electric Vehicle, Vehicle | I21: 46087.352 | J21: DebugRecord | N21: EngineProtocolDetectedNewCode | AK21: 01-03-09-00-00-00-00-00-00-00-00-00-00-00-00
A22: NISSAN LEAF 299-1018 | B22: b3 | C22: Vehicle, Battery Electric Vehicle | D22: Battery Electric Vehicle, Vehicle | I22: 46087.352 | J22: EngineStatusRecord | AB22: Protocolo genérico de motor detectado abierto CAN 500k | AC22: aqQtXD0-yQkCeNspDwDF8cA | AE22: ControllerNoneId | AH22: 1 | AI22: None | AJ22: UnitOfMeasureNoneId
A23: NISSAN LEAF 299-1018 | B23: b3 | C23: Vehicle, Battery Electric Vehicle | D23: Battery Electric Vehicle, Vehicle | I23: 46087.352 | J23: EngineStatusRecord | AB23: Se ha detectado el tipo de arnés inteligente | AC23: aTWDkdT3qWEy_M_tENiZcdg | AE23: ControllerNoneId | AH23: 8 | AI23: None | AJ23: UnitOfMeasureNoneId
A24: NISSAN LEAF 299-1018 | B24: b3 | C24: Vehicle, Battery Electric Vehicle | D24: Battery Electric Vehicle, Vehicle | I24: 46087.352 | J24: EngineStatusRecord | AB24: Vehículo híbrido / eléctrico detectado | AC24: DiagnosticHybridVehicleDetectedId | AE24: ControllerNoneId | AH24: 1 | AI24: None | AJ24: UnitOfMeasureNoneId
A25: NISSAN LEAF 299-1018 | B25: b3 | C25: Vehicle, Battery Electric Vehicle | D25: Battery Electric Vehicle, Vehicle | I25: 46087.352 | J25: DebugRecord | N25: 62012 | AK25: 07-00-00-00-03-00-00-00-00-00-00-00-00-00-00
A26: NISSAN LEAF 299-1018 | B26: b3 | C26: Vehicle, Battery Electric Vehicle | D26: Battery Electric Vehicle, Vehicle | I26: 46087.352 | J26: DebugRecord | N26: CanBusStatusBetweenTrips | AK26: 00-83-00-E0-32-00-00-00-00-00-00-00-00-00-00
A27: NISSAN LEAF 299-1018 | B27: b3 | C27: Vehicle, Battery Electric Vehicle | D27: Battery Electric Vehicle, Vehicle | I27: 46087.352 | J27: EngineStatusRecord | AB27: Cinturón de seguridad del conductor (1. Desabrochado) | AC27: DiagnosticDriverSeatbeltId | AE27: ControllerNoneId | AH27: -1 | AI27: None | AJ27: UnitOfMeasureNoneId
A28: NISSAN LEAF 299-1018 | B28: b3 | C28: Vehicle, Battery Electric Vehicle | D28: Battery Electric Vehicle, Vehicle | I28: 46087.352 | J28: EngineStatusRecord | AB28: Posición de la marcha (#s negativo = marcha atrás / #s positivo = marcha adelante / 0 = punto muerto / 126 = estacionamiento / 127 = tracción / 129 = intermedio) | AC28: DiagnosticGearPositionId | AE28: ControllerNoneId | AH28: 126 | AI28: None | AJ28: UnitOfMeasureNoneId
A29: NISSAN LEAF 299-1018 | B29: b3 | C29: Vehicle, Battery Electric Vehicle | D29: Battery Electric Vehicle, Vehicle | I29: 46087.352 | J29: DebugRecord | N29: InitServerDetai | AK29: 00-00-00-00-00-00-00-00-00-00-00-00-00-00-00
A30: NISSAN LEAF 299-1018 | B30: b3 | C30: Vehicle, Battery Electric Vehicle | D30: Battery Electric Vehicle, Vehicle | I30: 46087.352 | J30: EngineStatusRecord | AB30: Datos del motor (0. Inactivo, 1. Activo) | AC30: DiagnosticEngineDataActiveId | AE30: ControllerNoneId | AH30: 1 | AI30: None | AJ30: UnitOfMeasureNoneId
A31: NISSAN LEAF 299-1018 | B31: b3 | C31: Vehicle, Battery Electric Vehicle | D31: Battery Electric Vehicle, Vehicle | I31: 46087.352 | J31: DebugRecord | N31: 60927 | AK31: 0B-00-01-03-01-00-00-00-00-00-00-00-00-00-00
A32: NISSAN LEAF 299-1018 | B32: b3 | C32: Vehicle, Battery Electric Vehicle | D32: Battery Electric Vehicle, Vehicle | I32: 46087.352 | J32: EngineStatusRecord | AB32: Odómetro | AC32: DiagnosticOdometerId | AE32: ControllerNoneId | AH32: 15895 | AI32: km | AJ32: UnitOfMeasureMetersId
A33: NISSAN LEAF 299-1018 | B33: b3 | C33: Vehicle, Battery Electric Vehicle | D33: Battery Electric Vehicle, Vehicle | I33: 46087.352 | J33: EngineStatusRecord | AB33: Odómetro sin procesar | AC33: DiagnosticRawOdometerId | AE33: ControllerNoneId | AH33: 15895 | AI33: km | AJ33: UnitOfMeasureMetersId
A34: NISSAN LEAF 299-1018 | B34: b3 | C34: Vehicle, Battery Electric Vehicle | D34: Battery Electric Vehicle, Vehicle | I34: 46087.352 | J34: EngineStatusRecord | AB34: Freno de estacionamiento (1. En) | AC34: DiagnosticParkingBrakeId | AE34: ControllerNoneId | AH34: 0 | AI34: None | AJ34: UnitOfMeasureNoneId
A35: NISSAN LEAF 299-1018 | B35: b3 | C35: Vehicle, Battery Electric Vehicle | D35: Battery Electric Vehicle, Vehicle | I35: 46087.352 | J35: EngineStatusRecord | AB35: Voltaje de arranque | AC35: DiagnosticCrankingVoltageId | AE35: ControllerNoneId | AH35: 11.89272 | AI35: V | AJ35: UnitOfMeasureVoltsId
A36: NISSAN LEAF 299-1018 | B36: b3 | C36: Vehicle, Battery Electric Vehicle | D36: Battery Electric Vehicle, Vehicle | I36: 46087.352 | J36: DebugRecord | N36: ExcessiveTxCanErrorsInShortPeriodOfTime | AK36: 00-00-7E-01-00-00-00-00-00-00-00-00-00-00-00
A37: NISSAN LEAF 299-1018 | B37: b3 | C37: Vehicle, Battery Electric Vehicle | D37: Battery Electric Vehicle, Vehicle | I37: 46087.352 | J37: GpsRecord | K37: 0 | L37: -84.04379 | M37: 9.93673 | N37: Next | O37: TRUE | P37: FALSE | Q37: FALSE | R37: FALSE | S37: FALSE | T37: FALSE | U37: FALSE | V37: FALSE | W37: FALSE | X37: TRUE | Y37: TRUE
A38: NISSAN LEAF 299-1018 | B38: b3 | C38: Vehicle, Battery Electric Vehicle | D38: Battery Electric Vehicle, Vehicle | I38: 46087.352 | J38: DebugRecord | N38: 50145 | AK38: 00-FF-01-03-18-03-18-00-00-00-00-00-00-00-00
A39: NISSAN LEAF 299-1018 | B39: b3 | C39: Vehicle, Battery Electric Vehicle | D39: Battery Electric Vehicle, Vehicle | I39: 46087.352 | J39: DebugRecord | N39: 61765 | AK39: 01-00-00-01-00-00-00-00-00-00-00-00-00-00-00
A40: NISSAN LEAF 299-1018 | B40: b3 | C40: Vehicle, Battery Electric Vehicle | D40: Battery Electric Vehicle, Vehicle | I40: 46087.352 | J40: DebugRecord | N40: ExcessiveTxCanErrorsInShortPeriodOfTime | AK40: 00-00-CF-01-00-00-00-00-00-00-00-00-00-00-00
...

Sheet Report
A1: Reporte de registro de datos y colisiones | C1: =Data!B2 -> 46091.35
A2: =Data!B1 -> Escuela de Ingenieria Electrica UCR
U3: Ubicación
A4: Fecha
A5: Desde | B5: =Data!B3 -> 46087.352
A6: Hasta | B6: =Data!B4 -> 46087.486
A7: Días | B7: =B6-B5 -> 0.1339885
A9: Huso horario | B9: =Data!B5 -> America/Costa_Rica
A10: Velocidad | B10: =Data!B6 -> km/h
A11: Total | B11: =COUNTA($A$14:$A$200000) -> 6537
A13: Vehículo | B13: Tiempo | C13: Detalles | D13: Ignición | E13: Tipo | F13: GPS | G13: Registro de errores depurados | H13: Diagnóstico del motor | I13: Controlador de motor | J13: Modo de Falla | K13: Estado del motor | L13: Grupo de dispositivos | M13: Nombre del Conductor | N13: Tiempo registrado | O13: Longitud | P13: Latitud | Q13: Motivo para el registro | R13: Velocidad | S13: Válido | T13: Tipo de Zona
A14: =Data!A11 -> NISSAN LEAF 299-1018 | B14: =N14 -> 46087.352 | C14: =IF(Data!J11="GpsRecord", CONCATENATE($U$3,": ",Data!M11,", ",Data!L11), CONCATENATE(Data!AB11, " ", Data!AH11)) -> Ubicación: 9.93678, -84.04376 | D14: =IF(Data!O11=TRUE(), "Yes", "No") -> Yes | E14: =IF(Data!J11="EngineStatusRecord","Engine",IF(Data!J11="GpsRecord", "GPS", IF(Data!J11="EngineFaultRecord", "Fault", IF(Data!J11="DriverChange","Driver",IF(Data!J11="CustomRecord","Custom","Debug"))))) -> GPS | F14: =IF(Data!Y11=TRUE(), "Yes", "No") -> Yes | G14: =Data!AK11 -> 0 | H14: =Data!AB11 -> 0 | I14: =Data!AD11 -> 0 | J14: =Data!AF11 -> 0 | K14: =CONCATENATE(Data!AH11, " ", Data!AI11) | L14: =Data!C11 -> Vehicle, Battery Electric Vehicle | M14: =Data!H11 -> 0 | N14: =Data!I11 -> 46087.352 | O14: =Data!L11 -> -84.04376 | P14: =Data!M11 -> 9.93678 | Q14: =IF(Data!N11=0,"",Data!N11) -> Ignition | R14: =Data!K11 -> 0 | S14: =IF(Data!X11=TRUE(), "Yes", "No") -> Yes | T14: =#REF! -> #REF!
A15: =Data!A12 -> NISSAN LEAF 299-1018 | B15: =N15 -> 46087.352 | C15: =IF(Data!J12="GpsRecord", CONCATENATE($U$3,": ",Data!M12,", ",Data!L12), CONCATENATE(Data!AB12, " ", Data!AH12)) -> PositionValidAtDevice 1 | D15: =IF(Data!O12=TRUE(), "Yes", "No") -> No | E15: =IF(Data!J12="EngineStatusRecord","Engine",IF(Data!J12="GpsRecord", "GPS", IF(Data!J12="EngineFaultRecord", "Fault", IF(Data!J12="DriverChange","Driver",IF(Data!J12="CustomRecord","Custom","Debug"))))) -> Engine | F15: =IF(Data!Y12=TRUE(), "Yes", "No") -> No | G15: =Data!AK12 -> 0 | H15: =Data!AB12 -> PositionValidAtDevice | I15: =Data!AD12 -> 0 | J15: =Data!AF12 -> 0 | K15: =CONCATENATE(Data!AH12, " ", Data!AI12) -> 1 None | L15: =Data!C12 -> Vehicle, Battery Electric Vehicle | M15: =Data!H12 -> 0 | N15: =Data!I12 -> 46087.352 | O15: =Data!L12 -> 0 | P15: =Data!M12 -> 0 | Q15: =IF(Data!N12=0,"",Data!N12) | R15: =Data!K12 -> 0 | S15: =IF(Data!X12=TRUE(), "Yes", "No") -> No | T15: =#REF! -> #REF!
A16: =Data!A13 -> NISSAN LEAF 299-1018 | B16: =N16 -> 46087.352 | C16: =IF(Data!J13="GpsRecord", CONCATENATE($U$3,": ",Data!M13,", ",Data!L13), CONCATENATE(Data!AB13, " ", Data!AH13)) -> Ignición 1 | D16: =IF(Data!O13=TRUE(), "Yes", "No") -> Yes | E16: =IF(Data!J13="EngineStatusRecord","Engine",IF(Data!J13="GpsRecord", "GPS", IF(Data!J13="EngineFaultRecord", "Fault", IF(Data!J13="DriverChange","Driver",IF(Data!J13="CustomRecord","Custom","Debug"))))) -> Engine | F16: =IF(Data!Y13=TRUE(), "Yes", "No") -> No | G16: =Data!AK13 -> 0 | H16: =Data!AB13 -> Ignición | I16: =Data!AD13 -> 0 | J16: =Data!AF13 -> 0 | K16: =CONCATENATE(Data!AH13, " ", Data!AI13) -> 1 None | L16: =Data!C13 -> Vehicle, Battery Electric Vehicle | M16: =Data!H13 -> 0 | N16: =Data!I13 -> 46087.352 | O16: =Data!L13 -> 0 | P16: =Data!M13 -> 0 | Q16: =IF(Data!N13=0,"",Data!N13) | R16: =Data!K13 -> 0 | S16: =IF(Data!X13=TRUE(), "Yes", "No") -> No | T16: =#REF! -> #REF!
A17: =Data!A14 -> NISSAN LEAF 299-1018 | B17: =N17 -> 46087.352 | C17: =IF(Data!J14="GpsRecord", CONCATENATE($U$3,": ",Data!M14,", ",Data!L14), CONCATENATE(Data!AB14, " ", Data!AH14)) | D17: =IF(Data!O14=TRUE(), "Yes", "No") -> No | E17: =IF(Data!J14="EngineStatusRecord","Engine",IF(Data!J14="GpsRecord", "GPS", IF(Data!J14="EngineFaultRecord", "Fault", IF(Data!J14="DriverChange","Driver",IF(Data!J14="CustomRecord","Custom","Debug"))))) -> Debug | F17: =IF(Data!Y14=TRUE(), "Yes", "No") -> No | G17: =Data!AK14 -> FE-FE-FE-FE-FE-FE-FE-00-00-00-00-00-00-00-00 | H17: =Data!AB14 -> 0 | I17: =Data!AD14 -> 0 | J17: =Data!AF14 -> 0 | K17: =CONCATENATE(Data!AH14, " ", Data!AI14) | L17: =Data!C14 -> Vehicle, Battery Electric Vehicle | M17: =Data!H14 -> 0 | N17: =Data!I14 -> 46087.352 | O17: =Data!L14 -> 0 | P17: =Data!M14 -> 0 | Q17: =IF(Data!N14=0,"",Data!N14) -> ReportOnIoxsConnected | R17: =Data!K14 -> 0 | S17: =IF(Data!X14=TRUE(), "Yes", "No") -> No | T17: =#REF! -> #REF!
A18: =Data!A15 -> NISSAN LEAF 299-1018 | B18: =N18 -> 46087.352 | C18: =IF(Data!J15="GpsRecord", CONCATENATE($U$3,": ",Data!M15,", ",Data!L15), CONCATENATE(Data!AB15, " ", Data!AH15)) | D18: =IF(Data!O15=TRUE(), "Yes", "No") -> No | E18: =IF(Data!J15="EngineStatusRecord","Engine",IF(Data!J15="GpsRecord", "GPS", IF(Data!J15="EngineFaultRecord", "Fault", IF(Data!J15="DriverChange","Driver",IF(Data!J15="CustomRecord","Custom","Debug"))))) -> Debug | F18: =IF(Data!Y15=TRUE(), "Yes", "No") -> No | G18: =Data!AK15 -> 49-FC-FC-FF-26-00-00-00-00-00-00-00-00-00-00 | H18: =Data!AB15 -> 0 | I18: =Data!AD15 -> 0 | J18: =Data!AF15 -> 0 | K18: =CONCATENATE(Data!AH15, " ", Data!AI15) | L18: =Data!C15 -> Vehicle, Battery Electric Vehicle | M18: =Data!H15 -> 0 | N18: =Data!I15 -> 46087.352 | O18: =Data!L15 -> 0 | P18: =Data!M15 -> 0 | Q18: =IF(Data!N15=0,"",Data!N15) -> 61393 | R18: =Data!K15 -> 0 | S18: =IF(Data!X15=TRUE(), "Yes", "No") -> No | T18: =#REF! -> #REF!
A19: =Data!A16 -> NISSAN LEAF 299-1018 | B19: =N19 -> 46087.352 | C19: =IF(Data!J16="GpsRecord", CONCATENATE($U$3,": ",Data!M16,", ",Data!L16), CONCATENATE(Data!AB16, " ", Data!AH16)) | D19: =IF(Data!O16=TRUE(), "Yes", "No") -> No | E19: =IF(Data!J16="EngineStatusRecord","Engine",IF(Data!J16="GpsRecord", "GPS", IF(Data!J16="EngineFaultRecord", "Fault", IF(Data!J16="DriverChange","Driver",IF(Data!J16="CustomRecord","Custom","Debug"))))) -> Debug | F19: =IF(Data!Y16=TRUE(), "Yes", "No") -> No | G19: =Data!AK16 -> 56-01-55-01-50-01-00-00-00-00-00-00-00-00-00 | H19: =Data!AB16 -> 0 | I19: =Data!AD16 -> 0 | J19: =Data!AF16 -> 0 | K19: =CONCATENATE(Data!AH16, " ", Data!AI16) | L19: =Data!C16 -> Vehicle, Battery Electric Vehicle | M19: =Data!H16 -> 0 | N19: =Data!I16 -> 46087.352 | O19: =Data!L16 -> 0 | P19: =Data!M16 -> 0 | Q19: =IF(Data!N16=0,"",Data!N16) -> 61161 | R19: =Data!K16 -> 0 | S19: =IF(Data!X16=TRUE(), "Yes", "No") -> No | T19: =#REF! -> #REF!
A20: =Data!A17 -> NISSAN LEAF 299-1018 | B20: =N20 -> 46087.352 | C20: =IF(Data!J17="GpsRecord", CONCATENATE($U$3,": ",Data!M17,", ",Data!L17), CONCATENATE(Data!AB17, " ", Data!AH17)) -> Carburador de paso 6 | D20: =IF(Data!O17=TRUE(), "Yes", "No") -> No | E20: =IF(Data!J17="EngineStatusRecord","Engine",IF(Data!J17="GpsRecord", "GPS", IF(Data!J17="EngineFaultRecord", "Fault", IF(Data!J17="DriverChange","Driver",IF(Data!J17="CustomRecord","Custom","Debug"))))) -> Engine | F20: =IF(Data!Y17=TRUE(), "Yes", "No") -> No | G20: =Data!AK17 -> 0 | H20: =Data!AB17 -> Carburador de paso | I20: =Data!AD17 -> 0 | J20: =Data!AF17 -> 0 | K20: =CONCATENATE(Data!AH17, " ", Data!AI17) -> 6 None | L20: =Data!C17 -> Vehicle, Battery Electric Vehicle | M20: =Data!H17 -> 0 | N20: =Data!I17 -> 46087.352 | O20: =Data!L17 -> 0 | P20: =Data!M17 -> 0 | Q20: =IF(Data!N17=0,"",Data!N17) | R20: =Data!K17 -> 0 | S20: =IF(Data!X17=TRUE(), "Yes", "No") -> No | T20: =#REF! -> #REF!
A21: =Data!A18 -> NISSAN LEAF 299-1018 | B21: =N21 -> 46087.352 | C21: =IF(Data!J18="GpsRecord", CONCATENATE($U$3,": ",Data!M18,", ",Data!L18), CONCATENATE(Data!AB18, " ", Data!AH18)) -> Ubicación: 9.93678, -84.04376 | D21: =IF(Data!O18=TRUE(), "Yes", "No") -> Yes | E21: =IF(Data!J18="EngineStatusRecord","Engine",IF(Data!J18="GpsRecord", "GPS", IF(Data!J18="EngineFaultRecord", "Fault", IF(Data!J18="DriverChange","Driver",IF(Data!J18="CustomRecord","Custom","Debug"))))) -> GPS | F21: =IF(Data!Y18=TRUE(), "Yes", "No") -> Yes | G21: =Data!AK18 -> 0 | H21: =Data!AB18 -> 0 | I21: =Data!AD18 -> 0 | J21: =Data!AF18 -> 0 | K21: =CONCATENATE(Data!AH18, " ", Data!AI18) | L21: =Data!C18 -> Vehicle, Battery Electric Vehicle | M21: =Data!H18 -> 0 | N21: =Data!I18 -> 46087.352 | O21: =Data!L18 -> -84.04376 | P21: =Data!M18 -> 9.93678 | Q21: =IF(Data!N18=0,"",Data!N18) -> CurveOtherEvent | R21: =Data!K18 -> 0 | S21: =IF(Data!X18=TRUE(), "Yes", "No") -> Yes | T21: =#REF! -> #REF!
A22: =Data!A19 -> NISSAN LEAF 299-1018 | B22: =N22 -> 46087.352 | C22: =IF(Data!J19="GpsRecord", CONCATENATE($U$3,": ",Data!M19,", ",Data!L19), CONCATENATE(Data!AB19, " ", Data!AH19)) | D22: =IF(Data!O19=TRUE(), "Yes", "No") -> No | E22: =IF(Data!J19="EngineStatusRecord","Engine",IF(Data!J19="GpsRecord", "GPS", IF(Data!J19="EngineFaultRecord", "Fault", IF(Data!J19="DriverChange","Driver",IF(Data!J19="CustomRecord","Custom","Debug"))))) -> Debug | F22: =IF(Data!Y19=TRUE(), "Yes", "No") -> No | G22: =Data!AK19 -> 0B-01-00-01-01-00-00-00-00-00-00-00-00-00-00 | H22: =Data!AB19 -> 0 | I22: =Data!AD19 -> 0 | J22: =Data!AF19 -> 0 | K22: =CONCATENATE(Data!AH19, " ", Data!AI19) | L22: =Data!C19 -> Vehicle, Battery Electric Vehicle | M22: =Data!H19 -> 0 | N22: =Data!I19 -> 46087.352 | O22: =Data!L19 -> 0 | P22: =Data!M19 -> 0 | Q22: =IF(Data!N19=0,"",Data!N19) -> 60927 | R22: =Data!K19 -> 0 | S22: =IF(Data!X19=TRUE(), "Yes", "No") -> No | T22: =#REF! -> #REF!
A23: =Data!A20 -> NISSAN LEAF 299-1018 | B23: =N23 -> 46087.352 | C23: =IF(Data!J20="GpsRecord", CONCATENATE($U$3,": ",Data!M20,", ",Data!L20), CONCATENATE(Data!AB20, " ", Data!AH20)) -> Contrato de datos genéricos del vehículo activo 1 | D23: =IF(Data!O20=TRUE(), "Yes", "No") -> No | E23: =IF(Data!J20="EngineStatusRecord","Engine",IF(Data!J20="GpsRecord", "GPS", IF(Data!J20="EngineFaultRecord", "Fault", IF(Data!J20="DriverChange","Driver",IF(Data!J20="CustomRecord","Custom","Debug"))))) -> Engine | F23: =IF(Data!Y20=TRUE(), "Yes", "No") -> No | G23: =Data!AK20 -> 0 | H23: =Data!AB20 -> Contrato de datos genéricos del vehículo activo | I23: =Data!AD20 -> 0 | J23: =Data!AF20 -> 0 | K23: =CONCATENATE(Data!AH20, " ", Data!AI20) -> 1 None | L23: =Data!C20 -> Vehicle, Battery Electric Vehicle | M23: =Data!H20 -> 0 | N23: =Data!I20 -> 46087.352 | O23: =Data!L20 -> 0 | P23: =Data!M20 -> 0 | Q23: =IF(Data!N20=0,"",Data!N20) | R23: =Data!K20 -> 0 | S23: =IF(Data!X20=TRUE(), "Yes", "No") -> No | T23: =#REF! -> #REF!
A24: =Data!A21 -> NISSAN LEAF 299-1018 | B24: =N24 -> 46087.352 | C24: =IF(Data!J21="GpsRecord", CONCATENATE($U$3,": ",Data!M21,", ",Data!L21), CONCATENATE(Data!AB21, " ", Data!AH21)) | D24: =IF(Data!O21=TRUE(), "Yes", "No") -> No | E24: =IF(Data!J21="EngineStatusRecord","Engine",IF(Data!J21="GpsRecord", "GPS", IF(Data!J21="EngineFaultRecord", "Fault", IF(Data!J21="DriverChange","Driver",IF(Data!J21="CustomRecord","Custom","Debug"))))) -> Debug | F24: =IF(Data!Y21=TRUE(), "Yes", "No") -> No | G24: =Data!AK21 -> 01-03-09-00-00-00-00-00-00-00-00-00-00-00-00 | H24: =Data!AB21 -> 0 | I24: =Data!AD21 -> 0 | J24: =Data!AF21 -> 0 | K24: =CONCATENATE(Data!AH21, " ", Data!AI21) | L24: =Data!C21 -> Vehicle, Battery Electric Vehicle | M24: =Data!H21 -> 0 | N24: =Data!I21 -> 46087.352 | O24: =Data!L21 -> 0 | P24: =Data!M21 -> 0 | Q24: =IF(Data!N21=0,"",Data!N21) -> EngineProtocolDetectedNewCode | R24: =Data!K21 -> 0 | S24: =IF(Data!X21=TRUE(), "Yes", "No") -> No | T24: =#REF! -> #REF!
A25: =Data!A22 -> NISSAN LEAF 299-1018 | B25: =N25 -> 46087.352 | C25: =IF(Data!J22="GpsRecord", CONCATENATE($U$3,": ",Data!M22,", ",Data!L22), CONCATENATE(Data!AB22, " ", Data!AH22)) -> Protocolo genérico de motor detectado abierto CAN 500k 1 | D25: =IF(Data!O22=TRUE(), "Yes", "No") -> No | E25: =IF(Data!J22="EngineStatusRecord","Engine",IF(Data!J22="GpsRecord", "GPS", IF(Data!J22="EngineFaultRecord", "Fault", IF(Data!J22="DriverChange","Driver",IF(Data!J22="CustomRecord","Custom","Debug"))))) -> Engine | F25: =IF(Data!Y22=TRUE(), "Yes", "No") -> No | G25: =Data!AK22 -> 0 | H25: =Data!AB22 -> Protocolo genérico de motor detectado abierto CAN 500k | I25: =Data!AD22 -> 0 | J25: =Data!AF22 -> 0 | K25: =CONCATENATE(Data!AH22, " ", Data!AI22) -> 1 None | L25: =Data!C22 -> Vehicle, Battery Electric Vehicle | M25: =Data!H22 -> 0 | N25: =Data!I22 -> 46087.352 | O25: =Data!L22 -> 0 | P25: =Data!M22 -> 0 | Q25: =IF(Data!N22=0,"",Data!N22) | R25: =Data!K22 -> 0 | S25: =IF(Data!X22=TRUE(), "Yes", "No") -> No | T25: =#REF! -> #REF!
... A6550: =Data!A6547 -> NISSAN LEAF 299-1018 | B6550: =N6550 -> 46087.486 | C6550: =IF(Data!J6547="GpsRecord", CONCATENATE($U$3,": ",Data!M6547,", ",Data!L6547), CONCATENATE(Data!AB6547, " ", Data!AH6547)) -> Señal de giro hacia la derecha (1. En) 0 | D6550: =IF(Data!O6547=TRUE(), "Yes", "No") -> No | E6550: =IF(Data!J6547="EngineStatusRecord","Engine",IF(Data!J6547="GpsRecord", "GPS", IF(Data!J6547="EngineFaultRecord", "Fault", IF(Data!J6547="DriverChange","Driver",IF(Data!J6547="CustomRecord","Custom","Debug"))))) -> Engine | F6550: =IF(Data!Y6547=TRUE(), "Yes", "No") -> No | G6550: =Data!AK6547 -> 0 | H6550: =Data!AB6547 -> Señal de giro hacia la derecha (1. En) | I6550: =Data!AD6547 -> 0 | J6550: =Data!AF6547 -> 0 | K6550: =CONCATENATE(Data!AH6547, " ", Data!AI6547) -> 0 None | L6550: =Data!C6547 -> Vehicle, Battery Electric Vehicle | M6550: =Data!H6547 -> 0 | N6550: =Data!I6547 -> 46087.486 | O6550: =Data!L6547 -> 0 | P6550: =Data!M6547 -> 0 | Q6550: =IF(Data!N6547=0,"",Data!N6547) | R6550: =Data!K6547 -> 0 | S6550: =IF(Data!X6547=TRUE(), "Yes", "No") -> No | T6550: =#REF! -> #REF!

Sheet Summary
A1: Reporte de registro de datos y colisiones | F1: =Data!B2 -> 46091.35
A3: Desde | B3: =Data!B3 -> 46087.352
A4: Hasta | B4: =Data!B4 -> 46087.486
A5: Unidad de velocidad | B5: =Data!B6 -> km/h
A8: Ignición | B8: Diagnóstico del motor | C8: Controlador de motor | D8: Modo de Falla | E8: Estado del motor
A9: No | B9: 0 | C9: 0 | D9: 0
B10: PositionValidAtDevice | C10: 0 | D10: 0 | E10: 1 None
E11: 0 None
B12: Carburador de paso | C12: 0 | D12: 0 | E12: 6 None
B13: Contrato de datos genéricos del vehículo activo | C13: 0 | D13: 0 | E13: 1 None
B14: Protocolo genérico de motor detectado abierto CAN 500k | C14: 0 | D14: 0 | E14: 1 None
B15: Se ha detectado el tipo de arnés inteligente | C15: 0 | D15: 0 | E15: 8 None
B16: Vehículo híbrido / eléctrico detectado | C16: 0 | D16: 0 | E16: 1 None
B17: Cinturón de seguridad del conductor (1. Desabrochado) | C17: 0 | D17: 0 | E17: 1 None
E18: -1 None
E19: 0 None
B20: Posición de la marcha (#s negativo = marcha atrás / #s positivo = marcha adelante / 0 = punto muerto / 126 = estacionamiento / 127 = tracción / 129 = intermedio) | C20: 0 | D20: 0 | E20: -1 None
E21: 126 None
E22: 127 None
B23: Datos del motor (0. Inactivo, 1. Activo) | C23: 0 | D23: 0 | E23: 1 None
B24: Odómetro | C24: 0 | D24: 0 | E24: 15895 km
E25: 15897 km
E26: 15898 km
E27: 15900 km
E28: 15901 km
E29: 15902 km
E30: 15903 km
E31: 15904 km
E32: 15905 km
E33: 15906 km
E34: 15907 km
E35: 15908 km
E36: 15909 km
... E187: 16062 km
B188: Odómetro sin procesar | C188: 0 | D188: 0 | E188: 15895 km
E189: 15897 km
E190: 15898 km
E191: 15900 km
E192: 15901 km
E193: 15902 km
...

Sheet Languages
A1: English | B1: French Canada | C1: Spanish | D1: German | E1: Japanese | F1: Polish | G1: Portuguese-Brazil | H1: Dutch | I1: Italian | J1: Simplified Chinese | K1: Thai | L1: Indonesian | M1: Czech | N1: Swedish | O1: Turkish | P1: Malay | Q1: French France | R1: Korean | S1: Traditional Chinese | T1: Danish | U1: Finnish | V1: Hungarian | W1: Norwegian | X1: Slovak | Y1: Portuguese-Portugal | Z1: Romanian
A2: **Speed | B2: Vitesse | C2: Velocidad | D2: Geschwindigkeit | E2: スピード | F2: PREDKOSC | G2: VELOCIDADE | H2: SNELHEID | I2: VELOCITÀ | J2: 速度 | K2: ความเร็ว | L2: KECEPATAN | M2: RYCHLOST | N2: HASTIGHET | O2: Hız | P2: KELAJUAN | Q2: VITESSE | R2: 속도 | S2: 速度 | T2: Hastighed | U2: Nopeus | V2: Sebesség | W2: Hastighet | X2: Rýchlosť | Y2: Velocidade | Z2: Viteză
A3: **Created | B3: Créé | C3: Creado | D3: Angelegt | E3: 作成済 | F3: Utworzono | G3: Criado em | H3: Aangemaakt | I3: Creato | J3: 创建日期 | K3: สร้างแล้ว | L3: Dibuat | M3: Vytvořeno | N3: Skapad | O3: Oluşturuldu | P3: Dicipta | Q3: Créé | R3: 생성됨 | S3: 已建立 | T3: Oprettet | U3: Luotu | V3: Létrehozva | W3: Opprettet | X3: Vytvorené | Y3: Criado | Z3: Creat
A4: **Vehicle | B4: Véhicule | C4: Vehículo | D4: Fahrzeug | E4: 車両 | F4: Pojazd | G4: Veículo | H4: Voertuig | I4: Veicolo | J4: 车辆 | K4: รถ | L4: Kendaraan | M4: Vozidlo | N4: Fordon | O4: Araç | P4: Kenderaan | Q4: Véhicule | R4: 차량 | S4: 車輛 | T4: Køretøj | U4: Ajoneuvo | V4: Jármű | W4: Kjøretøy | X4: Vozidlo | Y4: Veículo | Z4: Vehicul
A5: **To | B5: Au | C5: Hasta | D5: Bis | E5: 終了日 | F5: Do | G5: Até | H5: Tot | I5: Al | J5: 至 | K5: ถึง | L5: Hingga | M5: Do/pro | N5: Till | O5: Alıcı | P5: Ke | Q5: À | R5: 대상 | S5: 至 | T5: Til | U5: Kohde | V5: Címzett | W5: Til | X5: Do | Y5: A | Z5: Către
A6: **Total | B6: Total | C6: Total | D6: Total | E6: 合計 | F6: Calkowita | G6: Total | H6: Totaal | I6: Totale | J6: 总计 | K6: ผลรวม | L6: Total | M6: Celkem | N6: Totalt | O6: Toplam | P6: Jumlah | Q6: Total | R6: 합계 | S6: 總計 | T6: I alt | U6: Yhteensä | V6: Összesen | W6: Totalt | X6: Celkove | Y6: Total | Z6: Total
A7: **Time | B7: Heure | C7: Tiempo | D7: Zeit | E7: 時間 | F7: Czas | G7: Hora | H7: Tijd | I7: Tempo | J7: 时间 | K7: เวลา | L7: Waktu | M7: Čas | N7: Tid | O7: Zaman | P7: Masa | Q7: Heure | R7: 시간 | S7: 時間 | T7: Tid | U7: Aika | V7: Idő | W7: Tid | X7: Čas | Y7: Hora | Z7: Oră
A8: **Details | B8: Détails | C8: Detalles | D8: Details | E8: 詳細 | F8: Szczególy | G8: Detalhes | H8: Details | I8: Dettagli | J8: 详细信息 | K8: รายละเอียด | L8: Detail | M8: Podrobnosti | N8: Detaljer | O8: Ayrıntılar | P8: Butiran | Q8: Détails | R8: 세부 정보 | S8: 詳細資訊 | T8: Detaljer | U8: Tarkemmat tiedot | V8: Részletek | W8: Detaljer | X8: Podrobnosti | Y8: Detalhes | Z8: Detalii
A9: **Ignition | B9: Système d'allumage | C9: Ignición | D9: Zündung | E9: IG | F9: Zaplon | G9: Ignição | H9: Ontsteking | I9: Accensione | J9: 点火 | K9: สวิตช์กุญแจ | L9: Pengapian | M9: Zapalování | N9: Tändning | O9: Kontak | P9: Pencucuhan | Q9: Allumage | R9: 점화 | S9: 點火 | T9: Tænding | U9: Käynnistys | V9: Gyújtás | W9: Tenning | X9: Zapaľovanie | Y9: Ignição | Z9: Aprindere
A10: **Type | B10: Type | C10: Tipo | D10: Typ | E10: 種類 | F10: Typ | G10: Tipo | H10: Type | I10: Tipo | J10: 类型 | K10: ประเภท | L10: Jenis | M10: Typ | N10: Typ | O10: Tür | P10: Jenis | Q10: Type | R10: 유형 | S10: 類型 | T10: Type | U10: Tyyppi | V10: Típus | W10: Type | X10: Typ | Y10: Tipo | Z10: Tip
A11: **Debug Record | B11: Fiche de dépannage | C11: Registro de errores depurados | D11: Fehlerbeseitigungsdatensatz | E11: デバッグ記録 | F11: Rekord analizy bledów | G11: Registro de Debug | H11: Registratie foutopsporing | I11: Record di debug | J11: 调试记录 | K11: บันทึกดีบัก | L11: Catatan Debug | M11: Zpráva o ladění | N11: Felsökningspost | O11: Hata Ayıklama Kaydı | P11: Rekod Nyahpepijat | Q11: Entrée de débug | R11: 디버그 기록 | S11: 偵錯記錄 | T11: Fejlretningsjournal | U11: Tee tietueen virheenkorjaus | V11: Hibaelhárítási nyilvántartás | W11: Feilsøkingspost | X11: Záznam ladenia | Y11: Registo de depuração | Z11: Debug Record
A12: **Engine Diagnostic | B12: Diagnostic du moteur | C12: Diagnóstico del motor | D12: Motordiagnose | E12: エンジン診断 | F12: Diagnostyka silnika | G12: Diagnóstico do motor | H12: Motordiagnose | I12: Diagnostica del motore | J12: 发动机诊断 | K12: การวินิจฉัยเครื่องยนต์ | L12: Diagnostik Mesin | M12: Diagnostika motoru | N12: Motordiagnostik | O12: Motor Tanısı | P12: Diagnostik Enjin | Q12: Diagnostic du moteur | R12: 엔진 진단 | S12: 引擎診斷 | T12: Motordiagnosticering | U12: Moottorin vianmääritys | V12: Motordiagnosztika | W12: Motordiagnose | X12: Diagnostika motora | Y12: Diagnóstico do motor | Z12: Diagnosticarea motorului
... A30: **Date | B30: Date | C30: Fecha | D30: Datum | E30: データ | F30: Data | G30: Data | H30: Datum | I30: Data | J30: 日期 | K30: วันที่ | L30: Tanggal | M30: Datum | N30: Datum | O30: Tarih | P30: Tarikh | Q30: Date | R30: 날짜 | S30: 日期 | T30: Dato | U30: Päivämäärä | V30: Dátum | W30: Dato | X30: Dátum | Y30: Data | Z30: Data
